Workbook

Sheet Dashboard
A1: PORSCHE | DASHBOARD DE VENDAS | P1: Modelos | Q1: Status
P2: Todos | Q2: Todos
A3: Painel interativo e autoeducativo — altere os filtros amarelos para explorar os dados. | P3: 718 Boxster | Q3: Awaiting Delivery
P4: 718 Boxster GTS | Q4: Awaiting Pickup
A5: FILTROS | P5: 718 Cayman | Q5: Awaiting Review
A6: Modelo | B6: Todos | C6: Status da entrega | D6: Todos | P6: 718 Cayman GT4 RS | Q6: Cancelled
P7: 718 Cayman S | Q7: Delivered
A8: TOTAL DE VENDAS | D8: FATURAMENTO | G8: TICKET MÉDIO | J8: QUILOMETRAGEM MÉDIA | P8: 718 Spyder RS | Q8: In Transit
A9: =SUMPRODUCT(--((Base_Dados!$D$2:$D$101=$B$6)+($B$6="Todos")>0),--((Base_Dados!$L$2:$L$101=$D$6)+($D$6="Todos")>0),--(Base_Dados!$F$2:$F$101<>"")) | D9: =SUMPRODUCT(((Base_Dados!$D$2:$D$101=$B$6)+($B$6="Todos")>0)*((Base_Dados!$L$2:$L$101=$D$6)+($D$6="Todos")>0)*N(Base_Dados!$F$2:$F$101)) | G9: =IFERROR(D9/A9,0) | J9: =IFERROR(SUMPRODUCT(((Base_Dados!$D$2:$D$101=$B$6)+($B$6="Todos")>0)*((Base_Dados!$L$2:$L$101=$D$6)+($D$6="Todos")>0)*N(Base_Dados!$G$2:$G$101))/A9,0) | P9: 911 Carrera | Q9: Pending
P10: 911 Carrera Cabriolet | Q10: Pending Approval
A11: COMO LER O PAINEL | P11: 911 Carrera GTS | Q11: Pending Review
A12: Total de vendas | D12: Faturamento | G12: Ticket médio | J12: Quilometragem média | P12: 911 Carrera S | Q12: Shipped
A13: quantidade de registros de vendas que atendem aos filtros. | D13: soma dos preços de venda após os filtros. | G13: faturamento dividido pelo número de vendas. | J13: média da quilometragem dos veículos filtrados. | P13: 911 Dakar
P14: 911 GT3
A15: VENDAS POR MODELO | E15: STATUS DE ENTREGA | H15: FORMA DE PAGAMENTO | P15: 911 GT3 RS
A16: Modelo | B16: Vendas | C16: Faturamento | E16: Status | F16: Vendas | H16: Forma | I16: Vendas | J16: Faturamento | P16: 911 Targa 4
A17: 718 Boxster | B17: =SUMPRODUCT(--((Base_Dados!$D$2:$D$101=A17)+($B$6="Todos")>0),--((Base_Dados!$L$2:$L$101=$D$6)+($D$6="Todos")>0),--(Base_Dados!$F$2:$F$101<>"")) | C17: =SUMPRODUCT(((Base_Dados!$D$2:$D$101=A17)+($B$6="Todos")>0)*((Base_Dados!$L$2:$L$101=$D$6)+($D$6="Todos")>0)*N(Base_Dados!$F$2:$F$101)) | E17: Awaiting Delivery | F17: =SUMPRODUCT(--((Base_Dados!$L$2:$L$101=E17)+($D$6="Todos")>0),--((Base_Dados!$D$2:$D$101=$B$6)+($B$6="Todos")>0),--(Base_Dados!$F$2:$F$101<>"")) | H17: ACH Payment | I17: =SUMPRODUCT(--((Base_Dados!$H$2:$H$101=H17)),--((Base_Dados!$D$2:$D$101=$B$6)+($B$6="Todos")>0),--((Base_Dados!$L$2:$L$101=$D$6)+($D$6="Todos")>0),--(Base_Dados!$F$2:$F$101<>"")) | J17: =SUMPRODUCT((Base_Dados!$H$2:$H$101=H17)*((Base_Dados!$D$2:$D$101=$B$6)+($B$6="Todos")>0)*((Base_Dados!$L$2:$L$101=$D$6)+($D$6="Todos")>0)*N(Base_Dados!$F$2:$F$101)) | P17: 911 Targa 4S
A18: 718 Boxster GTS | B18: =SUMPRODUCT(--((Base_Dados!$D$2:$D$101=A18)+($B$6="Todos")>0),--((Base_Dados!$L$2:$L$101=$D$6)+($D$6="Todos")>0),--(Base_Dados!$F$2:$F$101<>"")) | C18: =SUMPRODUCT(((Base_Dados!$D$2:$D$101=A18)+($B$6="Todos")>0)*((Base_Dados!$L$2:$L$101=$D$6)+($D$6="Todos")>0)*N(Base_Dados!$F$2:$F$101)) | E18: Awaiting Pickup | F18: =SUMPRODUCT(--((Base_Dados!$L$2:$L$101=E18)+($D$6="Todos")>0),--((Base_Dados!$D$2:$D$101=$B$6)+($B$6="Todos")>0),--(Base_Dados!$F$2:$F$101<>"")) | H18: Bank Transfer | I18: =SUMPRODUCT(--((Base_Dados!$H$2:$H$101=H18)),--((Base_Dados!$D$2:$D$101=$B$6)+($B$6="Todos")>0),--((Base_Dados!$L$2:$L$101=$D$6)+($D$6="Todos")>0),--(Base_Dados!$F$2:$F$101<>"")) | J18: =SUMPRODUCT((Base_Dados!$H$2:$H$101=H18)*((Base_Dados!$D$2:$D$101=$B$6)+($B$6="Todos")>0)*((Base_Dados!$L$2:$L$101=$D$6)+($D$6="Todos")>0)*N(Base_Dados!$F$2:$F$101)) | P18: 911 Turbo
A19: 718 Cayman | B19: =SUMPRODUCT(--((Base_Dados!$D$2:$D$101=A19)+($B$6="Todos")>0),--((Base_Dados!$L$2:$L$101=$D$6)+($D$6="Todos")>0),--(Base_Dados!$F$2:$F$101<>"")) | C19: =SUMPRODUCT(((Base_Dados!$D$2:$D$101=A19)+($B$6="Todos")>0)*((Base_Dados!$L$2:$L$101=$D$6)+($D$6="Todos")>0)*N(Base_Dados!$F$2:$F$101)) | E19: Awaiting Review | F19: =SUMPRODUCT(--((Base_Dados!$L$2:$L$101=E19)+($D$6="Todos")>0),--((Base_Dados!$D$2:$D$101=$B$6)+($B$6="Todos")>0),--(Base_Dados!$F$2:$F$101<>"")) | H19: Cash | I19: =SUMPRODUCT(--((Base_Dados!$H$2:$H$101=H19)),--((Base_Dados!$D$2:$D$101=$B$6)+($B$6="Todos")>0),--((Base_Dados!$L$2:$L$101=$D$6)+($D$6="Todos")>0),--(Base_Dados!$F$2:$F$101<>"")) | J19: =SUMPRODUCT((Base_Dados!$H$2:$H$101=H19)*((Base_Dados!$D$2:$D$101=$B$6)+($B$6="Todos")>0)*((Base_Dados!$L$2:$L$101=$D$6)+($D$6="Todos")>0)*N(Base_Dados!$F$2:$F$101)) | P19: 911 Turbo S
A20: 718 Cayman GT4 RS | B20: =SUMPRODUCT(--((Base_Dados!$D$2:$D$101=A20)+($B$6="Todos")>0),--((Base_Dados!$L$2:$L$101=$D$6)+($D$6="Todos")>0),--(Base_Dados!$F$2:$F$101<>"")) | C20: =SUMPRODUCT(((Base_Dados!$D$2:$D$101=A20)+($B$6="Todos")>0)*((Base_Dados!$L$2:$L$101=$D$6)+($D$6="Todos")>0)*N(Base_Dados!$F$2:$F$101)) | E20: Cancelled | F20: =SUMPRODUCT(--((Base_Dados!$L$2:$L$101=E20)+($D$6="Todos")>0),--((Base_Dados!$D$2:$D$101=$B$6)+($B$6="Todos")>0),--(Base_Dados!$F$2:$F$101<>"")) | H20: Credit Card | I20: =SUMPRODUCT(--((Base_Dados!$H$2:$H$101=H20)),--((Base_Dados!$D$2:$D$101=$B$6)+($B$6="Todos")>0),--((Base_Dados!$L$2:$L$101=$D$6)+($D$6="Todos")>0),--(Base_Dados!$F$2:$F$101<>"")) | J20: =SUMPRODUCT((Base_Dados!$H$2:$H$101=H20)*((Base_Dados!$D$2:$D$101=$B$6)+($B$6="Todos")>0)*((Base_Dados!$L$2:$L$101=$D$6)+($D$6="Todos")>0)*N(Base_Dados!$F$2:$F$101)) | P20: Cayenne
A21: 718 Cayman S | B21: =SUMPRODUCT(--((Base_Dados!$D$2:$D$101=A21)+($B$6="Todos")>0),--((Base_Dados!$L$2:$L$101=$D$6)+($D$6="Todos")>0),--(Base_Dados!$F$2:$F$101<>"")) | C21: =SUMPRODUCT(((Base_Dados!$D$2:$D$101=A21)+($B$6="Todos")>0)*((Base_Dados!$L$2:$L$101=$D$6)+($D$6="Todos")>0)*N(Base_Dados!$F$2:$F$101)) | E21: Delivered | F21: =SUMPRODUCT(--((Base_Dados!$L$2:$L$101=E21)+($D$6="Todos")>0),--((Base_Dados!$D$2:$D$101=$B$6)+($B$6="Todos")>0),--(Base_Dados!$F$2:$F$101<>"")) | H21: Crypto Payment | I21: =SUMPRODUCT(--((Base_Dados!$H$2:$H$101=H21)),--((Base_Dados!$D$2:$D$101=$B$6)+($B$6="Todos")>0),--((Base_Dados!$L$2:$L$101=$D$6)+($D$6="Todos")>0),--(Base_Dados!$F$2:$F$101<>"")) | J21: =SUMPRODUCT((Base_Dados!$H$2:$H$101=H21)*((Base_Dados!$D$2:$D$101=$B$6)+($B$6="Todos")>0)*((Base_Dados!$L$2:$L$101=$D$6)+($D$6="Todos")>0)*N(Base_Dados!$F$2:$F$101)) | P21: Cayenne Coupe
A22: 718 Spyder RS | B22: =SUMPRODUCT(--((Base_Dados!$D$2:$D$101=A22)+($B$6="Todos")>0),--((Base_Dados!$L$2:$L$101=$D$6)+($D$6="Todos")>0),--(Base_Dados!$F$2:$F$101<>"")) | C22: =SUMPRODUCT(((Base_Dados!$D$2:$D$101=A22)+($B$6="Todos")>0)*((Base_Dados!$L$2:$L$101=$D$6)+($D$6="Todos")>0)*N(Base_Dados!$F$2:$F$101)) | E22: In Transit | F22: =SUMPRODUCT(--((Base_Dados!$L$2:$L$101=E22)+($D$6="Todos")>0),--((Base_Dados!$D$2:$D$101=$B$6)+($B$6="Todos")>0),--(Base_Dados!$F$2:$F$101<>"")) | H22: Debit Card | I22: =SUMPRODUCT(--((Base_Dados!$H$2:$H$101=H22)),--((Base_Dados!$D$2:$D$101=$B$6)+($B$6="Todos")>0),--((Base_Dados!$L$2:$L$101=$D$6)+($D$6="Todos")>0),--(Base_Dados!$F$2:$F$101<>"")) | J22: =SUMPRODUCT((Base_Dados!$H$2:$H$101=H22)*((Base_Dados!$D$2:$D$101=$B$6)+($B$6="Todos")>0)*((Base_Dados!$L$2:$L$101=$D$6)+($D$6="Todos")>0)*N(Base_Dados!$F$2:$F$101)) | P22: Cayenne E-Hybrid
A23: 911 Carrera | B23: =SUMPRODUCT(--((Base_Dados!$D$2:$D$101=A23)+($B$6="Todos")>0),--((Base_Dados!$L$2:$L$101=$D$6)+($D$6="Todos")>0),--(Base_Dados!$F$2:$F$101<>"")) | C23: =SUMPRODUCT(((Base_Dados!$D$2:$D$101=A23)+($B$6="Todos")>0)*((Base_Dados!$L$2:$L$101=$D$6)+($D$6="Todos")>0)*N(Base_Dados!$F$2:$F$101)) | E23: Pending | F23: =SUMPRODUCT(--((Base_Dados!$L$2:$L$101=E23)+($D$6="Todos")>0),--((Base_Dados!$D$2:$D$101=$B$6)+($B$6="Todos")>0),--(Base_Dados!$F$2:$F$101<>"")) | H23: Financing | I23: =SUMPRODUCT(--((Base_Dados!$H$2:$H$101=H23)),--((Base_Dados!$D$2:$D$101=$B$6)+($B$6="Todos")>0),--((Base_Dados!$L$2:$L$101=$D$6)+($D$6="Todos")>0),--(Base_Dados!$F$2:$F$101<>"")) | J23: =SUMPRODUCT((Base_Dados!$H$2:$H$101=H23)*((Base_Dados!$D$2:$D$101=$B$6)+($B$6="Todos")>0)*((Base_Dados!$L$2:$L$101=$D$6)+($D$6="Todos")>0)*N(Base_Dados!$F$2:$F$101)) | P23: Cayenne S
A24: 911 Carrera Cabriolet | B24: =SUMPRODUCT(--((Base_Dados!$D$2:$D$101=A24)+($B$6="Todos")>0),--((Base_Dados!$L$2:$L$101=$D$6)+($D$6="Todos")>0),--(Base_Dados!$F$2:$F$101<>"")) | C24: =SUMPRODUCT(((Base_Dados!$D$2:$D$101=A24)+($B$6="Todos")>0)*((Base_Dados!$L$2:$L$101=$D$6)+($D$6="Todos")>0)*N(Base_Dados!$F$2:$F$101)) | E24: Pending Approval | F24: =SUMPRODUCT(--((Base_Dados!$L$2:$L$101=E24)+($D$6="Todos")>0),--((Base_Dados!$D$2:$D$101=$B$6)+($B$6="Todos")>0),--(Base_Dados!$F$2:$F$101<>"")) | H24: Lease | I24: =SUMPRODUCT(--((Base_Dados!$H$2:$H$101=H24)),--((Base_Dados!$D$2:$D$101=$B$6)+($B$6="Todos")>0),--((Base_Dados!$L$2:$L$101=$D$6)+($D$6="Todos")>0),--(Base_Dados!$F$2:$F$101<>"")) | J24: =SUMPRODUCT((Base_Dados!$H$2:$H$101=H24)*((Base_Dados!$D$2:$D$101=$B$6)+($B$6="Todos")>0)*((Base_Dados!$L$2:$L$101=$D$6)+($D$6="Todos")>0)*N(Base_Dados!$F$2:$F$101)) | P24: Cayenne Turbo
A25: 911 Carrera GTS | B25: =SUMPRODUCT(--((Base_Dados!$D$2:$D$101=A25)+($B$6="Todos")>0),--((Base_Dados!$L$2:$L$101=$D$6)+($D$6="Todos")>0),--(Base_Dados!$F$2:$F$101<>"")) | C25: =SUMPRODUCT(((Base_Dados!$D$2:$D$101=A25)+($B$6="Todos")>0)*((Base_Dados!$L$2:$L$101=$D$6)+($D$6="Todos")>0)*N(Base_Dados!$F$2:$F$101)) | E25: Pending Review | F25: =SUMPRODUCT(--((Base_Dados!$L$2:$L$101=E25)+($D$6="Todos")>0),--((Base_Dados!$D$2:$D$101=$B$6)+($B$6="Todos")>0),--(Base_Dados!$F$2:$F$101<>"")) | H25: Wire Transfer | I25: =SUMPRODUCT(--((Base_Dados!$H$2:$H$101=H25)),--((Base_Dados!$D$2:$D$101=$B$6)+($B$6="Todos")>0),--((Base_Dados!$L$2:$L$101=$D$6)+($D$6="Todos")>0),--(Base_Dados!$F$2:$F$101<>"")) | J25: =SUMPRODUCT((Base_Dados!$H$2:$H$101=H25)*((Base_Dados!$D$2:$D$101=$B$6)+($B$6="Todos")>0)*((Base_Dados!$L$2:$L$101=$D$6)+($D$6="Todos")>0)*N(Base_Dados!$F$2:$F$101)) | P25: Cayenne Turbo GT
A26: 911 Carrera S | B26: =SUMPRODUCT(--((Base_Dados!$D$2:$D$101=A26)+($B$6="Todos")>0),--((Base_Dados!$L$2:$L$101=$D$6)+($D$6="Todos")>0),--(Base_Dados!$F$2:$F$101<>"")) | C26: =SUMPRODUCT(((Base_Dados!$D$2:$D$101=A26)+($B$6="Todos")>0)*((Base_Dados!$L$2:$L$101=$D$6)+($D$6="Todos")>0)*N(Base_Dados!$F$2:$F$101)) | E26: Shipped | F26: =SUMPRODUCT(--((Base_Dados!$L$2:$L$101=E26)+($D$6="Todos")>0),--((Base_Dados!$D$2:$D$101=$B$6)+($B$6="Todos")>0),--(Base_Dados!$F$2:$F$101<>"")) | P26: Macan
A27: 911 Dakar | B27: =SUMPRODUCT(--((Base_Dados!$D$2:$D$101=A27)+($B$6="Todos")>0),--((Base_Dados!$L$2:$L$101=$D$6)+($D$6="Todos")>0),--(Base_Dados!$F$2:$F$101<>"")) | C27: =SUMPRODUCT(((Base_Dados!$D$2:$D$101=A27)+($B$6="Todos")>0)*((Base_Dados!$L$2:$L$101=$D$6)+($D$6="Todos")>0)*N(Base_Dados!$F$2:$F$101)) | P27: Macan Electric
A28: 911 GT3 | B28: =SUMPRODUCT(--((Base_Dados!$D$2:$D$101=A28)+($B$6="Todos")>0),--((Base_Dados!$L$2:$L$101=$D$6)+($D$6="Todos")>0),--(Base_Dados!$F$2:$F$101<>"")) | C28: =SUMPRODUCT(((Base_Dados!$D$2:$D$101=A28)+($B$6="Todos")>0)*((Base_Dados!$L$2:$L$101=$D$6)+($D$6="Todos")>0)*N(Base_Dados!$F$2:$F$101)) | P28: Macan GTS
A29: 911 GT3 RS | B29: =SUMPRODUCT(--((Base_Dados!$D$2:$D$101=A29)+($B$6="Todos")>0),--((Base_Dados!$L$2:$L$101=$D$6)+($D$6="Todos")>0),--(Base_Dados!$F$2:$F$101<>"")) | C29: =SUMPRODUCT(((Base_Dados!$D$2:$D$101=A29)+($B$6="Todos")>0)*((Base_Dados!$L$2:$L$101=$D$6)+($D$6="Todos")>0)*N(Base_Dados!$F$2:$F$101)) | P29: Macan S
A30: 911 Targa 4 | B30: =SUMPRODUCT(--((Base_Dados!$D$2:$D$101=A30)+($B$6="Todos")>0),--((Base_Dados!$L$2:$L$101=$D$6)+($D$6="Todos")>0),--(Base_Dados!$F$2:$F$101<>"")) | C30: =SUMPRODUCT(((Base_Dados!$D$2:$D$101=A30)+($B$6="Todos")>0)*((Base_Dados!$L$2:$L$101=$D$6)+($D$6="Todos")>0)*N(Base_Dados!$F$2:$F$101)) | P30: Macan T
A31: 911 Targa 4S | B31: =SUMPRODUCT(--((Base_Dados!$D$2:$D$101=A31)+($B$6="Todos")>0),--((Base_Dados!$L$2:$L$101=$D$6)+($D$6="Todos")>0),--(Base_Dados!$F$2:$F$101<>"")) | C31: =SUMPRODUCT(((Base_Dados!$D$2:$D$101=A31)+($B$6="Todos")>0)*((Base_Dados!$L$2:$L$101=$D$6)+($D$6="Todos")>0)*N(Base_Dados!$F$2:$F$101)) | P31: Panamera
A32: 911 Turbo | B32: =SUMPRODUCT(--((Base_Dados!$D$2:$D$101=A32)+($B$6="Todos")>0),--((Base_Dados!$L$2:$L$101=$D$6)+($D$6="Todos")>0),--(Base_Dados!$F$2:$F$101<>"")) | C32: =SUMPRODUCT(((Base_Dados!$D$2:$D$101=A32)+($B$6="Todos")>0)*((Base_Dados!$L$2:$L$101=$D$6)+($D$6="Todos")>0)*N(Base_Dados!$F$2:$F$101)) | P32: Panamera 4
A33: 911 Turbo S | B33: =SUMPRODUCT(--((Base_Dados!$D$2:$D$101=A33)+($B$6="Todos")>0),--((Base_Dados!$L$2:$L$101=$D$6)+($D$6="Todos")>0),--(Base_Dados!$F$2:$F$101<>"")) | C33: =SUMPRODUCT(((Base_Dados!$D$2:$D$101=A33)+($B$6="Todos")>0)*((Base_Dados!$L$2:$L$101=$D$6)+($D$6="Todos")>0)*N(Base_Dados!$F$2:$F$101)) | P33: Panamera 4 E-Hybrid
A34: Cayenne | B34: =SUMPRODUCT(--((Base_Dados!$D$2:$D$101=A34)+($B$6="Todos")>0),--((Base_Dados!$L$2:$L$101=$D$6)+($D$6="Todos")>0),--(Base_Dados!$F$2:$F$101<>"")) | C34: =SUMPRODUCT(((Base_Dados!$D$2:$D$101=A34)+($B$6="Todos")>0)*((Base_Dados!$L$2:$L$101=$D$6)+($D$6="Todos")>0)*N(Base_Dados!$F$2:$F$101)) | P34: Panamera 4S
A35: Cayenne Coupe | B35: =SUMPRODUCT(--((Base_Dados!$D$2:$D$101=A35)+($B$6="Todos")>0),--((Base_Dados!$L$2:$L$101=$D$6)+($D$6="Todos")>0),--(Base_Dados!$F$2:$F$101<>"")) | C35: =SUMPRODUCT(((Base_Dados!$D$2:$D$101=A35)+($B$6="Todos")>0)*((Base_Dados!$L$2:$L$101=$D$6)+($D$6="Todos")>0)*N(Base_Dados!$F$2:$F$101)) | P35: Panamera Turbo
A36: Cayenne E-Hybrid | B36: =SUMPRODUCT(--((Base_Dados!$D$2:$D$101=A36)+($B$6="Todos")>0),--((Base_Dados!$L$2:$L$101=$D$6)+($D$6="Todos")>0),--(Base_Dados!$F$2:$F$101<>"")) | C36: =SUMPRODUCT(((Base_Dados!$D$2:$D$101=A36)+($B$6="Todos")>0)*((Base_Dados!$L$2:$L$101=$D$6)+($D$6="Todos")>0)*N(Base_Dados!$F$2:$F$101)) | P36: Panamera Turbo S
A37: Cayenne S | B37: =SUMPRODUCT(--((Base_Dados!$D$2:$D$101=A37)+($B$6="Todos")>0),--((Base_Dados!$L$2:$L$101=$D$6)+($D$6="Todos")>0),--(Base_Dados!$F$2:$F$101<>"")) | C37: =SUMPRODUCT(((Base_Dados!$D$2:$D$101=A37)+($B$6="Todos")>0)*((Base_Dados!$L$2:$L$101=$D$6)+($D$6="Todos")>0)*N(Base_Dados!$F$2:$F$101)) | P37: Taycan
A38: Cayenne Turbo | B38: =SUMPRODUCT(--((Base_Dados!$D$2:$D$101=A38)+($B$6="Todos")>0),--((Base_Dados!$L$2:$L$101=$D$6)+($D$6="Todos")>0),--(Base_Dados!$F$2:$F$101<>"")) | C38: =SUMPRODUCT(((Base_Dados!$D$2:$D$101=A38)+($B$6="Todos")>0)*((Base_Dados!$L$2:$L$101=$D$6)+($D$6="Todos")>0)*N(Base_Dados!$F$2:$F$101)) | P38: Taycan 4S
... A42: Macan GTS | B42: =SUMPRODUCT(--((Base_Dados!$D$2:$D$101=A42)+($B$6="Todos")>0),--((Base_Dados!$L$2:$L$101=$D$6)+($D$6="Todos")>0),--(Base_Dados!$F$2:$F$101<>"")) | C42: =SUMPRODUCT(((Base_Dados!$D$2:$D$101=A42)+($B$6="Todos")>0)*((Base_Dados!$L$2:$L$101=$D$6)+($D$6="Todos")>0)*N(Base_Dados!$F$2:$F$101)) | P42: Taycan Turbo S
A43: Macan S | B43: =SUMPRODUCT(--((Base_Dados!$D$2:$D$101=A43)+($B$6="Todos")>0),--((Base_Dados!$L$2:$L$101=$D$6)+($D$6="Todos")>0),--(Base_Dados!$F$2:$F$101<>"")) | C43: =SUMPRODUCT(((Base_Dados!$D$2:$D$101=A43)+($B$6="Todos")>0)*((Base_Dados!$L$2:$L$101=$D$6)+($D$6="Todos")>0)*N(Base_Dados!$F$2:$F$101))
...

Sheet Base_Dados
A1: sale_id | B1: SaleDateSanitized | C1: customer_name | D1: PorscheModelSanitized | E1: ModelYearSanitized | F1: SalesPriceSanitized | G1: VehicleMileageSanitized | H1: PayMethodSanitized | I1: CitySanitized | J1: StateSanitized | K1: salesperson | L1: DeliveryStatusSanitized | M1: Data_Valida | N1: Ano | O1: Mes | P1: Mes_Ano | Q1: Faixa_Preco
A2: 6 | B2: INVALID | C2: Michael Adams | D2: 718 Cayman | E2: 2022 | F2: 79500 | G2: 9800 | H2: Credit Card | I2: Boston | J2: MA | K2: kevin | L2: Delivered | M2: =IFERROR(DATEVALUE(B2),"") | N2: =IF(M2="","",YEAR(M2)) | O2: =IF(M2="","",TEXT(M2,"mmm")) | P2: =IF(M2="","",TEXT(M2,"mmm/yyyy")) | Q2: =IF(F2="","",IF(F2<75000,"Até US$ 75 mil",IF(F2<100000,"US$ 75–100 mil",IF(F2<150000,"US$ 100–150 mil","Acima de US$ 150 mil"))))
A3: 7 | B3: 2024-03-14 | C3: SOPHIA Miller | D3: 911 Turbo S | E3: 2024 | F3: 235000 | G3: 1200 | H3: Wire Transfer | I3: Seattle | J3: WA | K3: AMANDA scott | L3: Delivered | M3: =IFERROR(DATEVALUE(B3),"") | N3: =IF(M3="","",YEAR(M3)) | O3: =IF(M3="","",TEXT(M3,"mmm")) | P3: =IF(M3="","",TEXT(M3,"mmm/yyyy")) | Q3: =IF(F3="","",IF(F3<75000,"Até US$ 75 mil",IF(F3<100000,"US$ 75–100 mil",IF(F3<150000,"US$ 100–150 mil","Acima de US$ 150 mil"))))
A4: 8 | B4: 2024-04-18 | C4: Daniel-Jones | D4: Cayenne Coupe | E4: 2023 | F4: 112750 | G4: 6400 | H4: Financing | I4: Austin | J4: TX | K4: Brian Hall | L4: In Transit | M4: =IFERROR(DATEVALUE(B4),"") | N4: =IF(M4="","",YEAR(M4)) | O4: =IF(M4="","",TEXT(M4,"mmm")) | P4: =IF(M4="","",TEXT(M4,"mmm/yyyy")) | Q4: =IF(F4="","",IF(F4<75000,"Até US$ 75 mil",IF(F4<100000,"US$ 75–100 mil",IF(F4<150000,"US$ 100–150 mil","Acima de US$ 150 mil"))))
A5: 9 | B5: INVALID | C5: Olivia Brown | D5: Macan S | E5: 2021 | F5: 68900 | G5: 28 | H5: Cash | I5: Denver | J5: CO | K5: jessica | L5: Pending | M5: =IFERROR(DATEVALUE(B5),"") | N5: =IF(M5="","",YEAR(M5)) | O5: =IF(M5="","",TEXT(M5,"mmm")) | P5: =IF(M5="","",TEXT(M5,"mmm/yyyy")) | Q5: =IF(F5="","",IF(F5<75000,"Até US$ 75 mil",IF(F5<100000,"US$ 75–100 mil",IF(F5<150000,"US$ 100–150 mil","Acima de US$ 150 mil"))))
A6: 10 | B6: 2024-05-22 | C6: Ethan Wilson | D6: Taycan 4S | E6: 2024 | F6: 121000 | G6: 0 | H6: Bank Transfer | I6: Los Angeles | J6: CA | K6: Thomas King | L6: Delivered | M6: =IFERROR(DATEVALUE(B6),"") | N6: =IF(M6="","",YEAR(M6)) | O6: =IF(M6="","",TEXT(M6,"mmm")) | P6: =IF(M6="","",TEXT(M6,"mmm/yyyy")) | Q6: =IF(F6="","",IF(F6<75000,"Até US$ 75 mil",IF(F6<100000,"US$ 75–100 mil",IF(F6<150000,"US$ 100–150 mil","Acima de US$ 150 mil"))))
A7: 11 | B7: 2024-08-06 | C7: Ava Martinez | D7: Panamera 4 | E7: 2023 | F7: 104500 | G7: 14500 | H7: Credit Card | I7: Miami | J7: FL | K7: LISA ray | L7: Cancelled | M7: =IFERROR(DATEVALUE(B7),"") | N7: =IF(M7="","",YEAR(M7)) | O7: =IF(M7="","",TEXT(M7,"mmm")) | P7: =IF(M7="","",TEXT(M7,"mmm/yyyy")) | Q7: =IF(F7="","",IF(F7<75000,"Até US$ 75 mil",IF(F7<100000,"US$ 75–100 mil",IF(F7<150000,"US$ 100–150 mil","Acima de US$ 150 mil"))))
A8: 12 | B8: 2024-07-11 | C8: Noah Davis | D8: 911 Carrera S | E8: 2020 | F8: 96300 | G8: 41000 | H8: Lease | I8: New York | J8: NY | K8: Mark Evans | L8: Delivered | M8: =IFERROR(DATEVALUE(B8),"") | N8: =IF(M8="","",YEAR(M8)) | O8: =IF(M8="","",TEXT(M8,"mmm")) | P8: =IF(M8="","",TEXT(M8,"mmm/yyyy")) | Q8: =IF(F8="","",IF(F8<75000,"Até US$ 75 mil",IF(F8<100000,"US$ 75–100 mil",IF(F8<150000,"US$ 100–150 mil","Acima de US$ 150 mil"))))
A9: 13 | B9: INVALID | C9: Isabella Garcia | D9: Cayenne E-Hybrid | E9: 2022 | F9: 89750 | G9: 11744 | H9: Wire Transfer | I9: San Diego | J9: CA | K9: nancy reed | L9: Pending Approval | M9: =IFERROR(DATEVALUE(B9),"") | N9: =IF(M9="","",YEAR(M9)) | O9: =IF(M9="","",TEXT(M9,"mmm")) | P9: =IF(M9="","",TEXT(M9,"mmm/yyyy")) | Q9: =IF(F9="","",IF(F9<75000,"Até US$ 75 mil",IF(F9<100000,"US$ 75–100 mil",IF(F9<150000,"US$ 100–150 mil","Acima de US$ 150 mil"))))
A10: 14 | B10: 2024-08-19 | C10: Liam Rodriguez | D10: 718 Boxster | E10: 2021 | F10: 73500 | G10: 22300 | H10: Debit Card | I10: Chicago | J10: IL | K10: George Bell | L10: Shipped | M10: =IFERROR(DATEVALUE(B10),"") | N10: =IF(M10="","",YEAR(M10)) | O10: =IF(M10="","",TEXT(M10,"mmm")) | P10: =IF(M10="","",TEXT(M10,"mmm/yyyy")) | Q10: =IF(F10="","",IF(F10<75000,"Até US$ 75 mil",IF(F10<100000,"US$ 75–100 mil",IF(F10<150000,"US$ 100–150 mil","Acima de US$ 150 mil"))))
A11: 15 | B11: 2024-09-02 | C11: Mia Hernandez | D11: Macan GTS | E11: 2024 | F11: 95000 | G11: 3500 | H11: Financing | I11: Phoenix | J11: AZ | K11: Helen Brooks | L11: In Transit | M11: =IFERROR(DATEVALUE(B11),"") | N11: =IF(M11="","",YEAR(M11)) | O11: =IF(M11="","",TEXT(M11,"mmm")) | P11: =IF(M11="","",TEXT(M11,"mmm/yyyy")) | Q11: =IF(F11="","",IF(F11<75000,"Até US$ 75 mil",IF(F11<100000,"US$ 75–100 mil",IF(F11<150000,"US$ 100–150 mil","Acima de US$ 150 mil"))))
A12: 16 | B12: 2024-09-17 | C12: James Lopez | D12: Taycan Turbo | E12: 2023 | F12: 153200.5 | G12: 11 | H12: ACH Payment | I12: Dallas | J12: TX | K12: samuel price | L12: Delivered | M12: =IFERROR(DATEVALUE(B12),"") | N12: =IF(M12="","",YEAR(M12)) | O12: =IF(M12="","",TEXT(M12,"mmm")) | P12: =IF(M12="","",TEXT(M12,"mmm/yyyy")) | Q12: =IF(F12="","",IF(F12<75000,"Até US$ 75 mil",IF(F12<100000,"US$ 75–100 mil",IF(F12<150000,"US$ 100–150 mil","Acima de US$ 150 mil"))))
A13: 17 | B13: INVALID | C13: Charlotte Young | D13: 911 GT3 | E13: 2024 | F13: 241000 | G13: 750 | H13: Wire Transfer | I13: Las Vegas | J13: NV | K13: PETER Ford | L13: Pending | M13: =IFERROR(DATEVALUE(B13),"") | N13: =IF(M13="","",YEAR(M13)) | O13: =IF(M13="","",TEXT(M13,"mmm")) | P13: =IF(M13="","",TEXT(M13,"mmm/yyyy")) | Q13: =IF(F13="","",IF(F13<75000,"Até US$ 75 mil",IF(F13<100000,"US$ 75–100 mil",IF(F13<150000,"US$ 100–150 mil","Acima de US$ 150 mil"))))
... A101: 105 | B101: 2027-10-01 | C101: Madison Powell | D101: 911 Dakar | E101: 2024 | F101: 271700 | G101: 1050 | H101: Lease | I101: New Orleans | J101: LA | K101: Steve Ross | L101: Delivered | M101: =IFERROR(DATEVALUE(B101),"") | N101: =IF(M101="","",YEAR(M101)) | O101: =IF(M101="","",TEXT(M101,"mmm")) | P101: =IF(M101="","",TEXT(M101,"mmm/yyyy")) | Q101: =IF(F101="","",IF(F101<75000,"Até US$ 75 mil",IF(F101<100000,"US$ 75–100 mil",IF(F101<150000,"US$ 100–150 mil","Acima de US$ 150 mil"))))

Sheet Guia_Autoeducativo
A1: GUIA AUTOEDUCATIVO — APRENDA EXCEL COM O DASHBOARD
A3: 1. Comece pelos filtros | B3: Na aba Dashboard, altere Modelo e Status. Observe como os quatro KPIs mudam automaticamente.
A4: 2. Entenda os KPIs | B4: Total de vendas = contagem; Faturamento = soma; Ticket médio = faturamento/vendas; Quilometragem média = média dos veículos filtrados.
A5: 3. Leia os gráficos | B5: O gráfico de barras mostra quais modelos concentram faturamento. O gráfico de pizza mostra a distribuição dos status.
A6: 4. Investigue a base | B6: Na aba Base_Dados, use os filtros da tabela para localizar vendas, modelos, preços, pagamentos e vendedores.
A7: 5. Estude as fórmulas | B7: Clique nas células dos KPIs e das tabelas-resumo para ver SUMPRODUCT, IFERROR e operações de agregação.
A8: 6. Faça perguntas | B8: Ex.: Qual modelo gera maior faturamento? Qual forma de pagamento aparece mais? Quantas vendas estão entregues?
A9: 7. Crie sua própria análise | B9: Copie uma tabela-resumo e altere o campo analisado. Tente trocar Modelo por vendedor, estado ou forma de pagamento.
A10: 8. Regra importante | B10: Os dados originais foram preservados. Registros com data INVALID não são corrigidos por suposição.
A14: DESAFIOS PRÁTICOS
A15: 1) Filtre um modelo e descubra seu ticket médio.
A16: 2) Filtre 'Delivered' e compare o faturamento com 'Pending'.
A17: 3) Identifique os 5 modelos com maior faturamento.
A18: 4) Descubra qual forma de pagamento possui maior faturamento.
A19: 5) Na Base_Dados, encontre quantos registros têm data INVALID.
A20: 6) Crie um gráfico novo por vendedor.

Sheet Dicionario
A1: Campo | B1: Descrição / finalidade | C1: Exemplo
A2: sale_id | B2: Identificador da venda | C2: 6
A3: SaleDateSanitized | B3: Data da venda; a fonte contém registros INVALID | C3: 2024-03-14
A4: customer_name | B4: Nome do cliente | C4: Michael Adams
A5: PorscheModelSanitized | B5: Modelo Porsche vendido | C5: 718 Cayman
A6: ModelYearSanitized | B6: Ano/model year do veículo | C6: 2024
A7: SalesPriceSanitized | B7: Preço da venda | C7: 235000
A8: VehicleMileageSanitized | B8: Quilometragem do veículo | C8: 1200
A9: PayMethodSanitized | B9: Forma de pagamento | C9: Wire Transfer
A10: CitySanitized | B10: Cidade | C10: Seattle
A11: StateSanitized | B11: Estado/UF | C11: WA
A12: salesperson | B12: Vendedor responsável | C12: Thomas King
... A18: Faixa_Preco | B18: Classificação didática do preço | C18: US$ 100–150 mil
